<?xml version="1.0" ?>
<sdf version="1.5">
  <model name="animat">
    <pose>0.0 0.0 0.1 0.0 0.0 0.0</pose>
    <link name="mori0_edge_0">
      <pose>0.0 0.0 0.0 0.0 0.0 0.0</pose>
      <inertial>
        <pose>0.07156417686898321 0.0185706718415633 0.0004234654444363972 0.0 0.0 0.0</pose>
        <mass>0.01924244181778677</mass>
        <inertia>
          <ixx>2.202818616618582e-12</ixx>
          <ixy>-5.510346292622388e-14</ixy>
          <ixz>-2.4501383091352336e-13</ixz>
          <iyy>9.55478060604246e-12</iyy>
          <iyz>3.6269644572832477e-14</iyz>
          <izz>1.136128573230277e-11</izz>
        </inertia>
      </inertial>
      <collision name="mori0_edge_0_collision">
        <pose>0.0 0.0 0.0 0.0 0.0 0.0</pose>
        <geometry>
          <mesh>
            <uri>/home/jonathan/Work/EPFL/PhD/Dev/FARMS/farms_amphibious/farms_amphibious/experiments/mori/meshes/mori_edge_0.stl</uri>
            <scale>0.001 0.001 0.001</scale>
          </mesh>
        </geometry>
      </collision>
      <visual name="mori0_edge_0_visual">
        <pose>0.0 0.0 0.0 0.0 0.0 0.0</pose>
        <geometry>
          <mesh>
            <uri>/home/jonathan/Work/EPFL/PhD/Dev/FARMS/farms_amphibious/farms_amphibious/experiments/mori/meshes/mori_edge_0.stl</uri>
            <scale>0.001 0.001 0.001</scale>
          </mesh>
        </geometry>
        <material/>
      </visual>
    </link>
    <link name="mori0_edge_1">
      <pose>0.18 0.0 0.0 0.0 0.0 0.0</pose>
      <inertial>
        <pose>-0.05608217366573354 0.01813392473990149 -0.0006412053342845109 0.0 0.0 0.0</pose>
        <mass>0.012487966796885032</mass>
        <inertia>
          <ixx>1.8853112716181517e-12</ixx>
          <ixy>-6.858507706102207e-13</ixy>
          <ixz>-1.0983686520414591e-13</ixz>
          <iyy>3.513265983945765e-12</iyy>
          <iyz>-3.8764347262766245e-14</iyz>
          <izz>5.143951490951159e-12</izz>
        </inertia>
      </inertial>
      <collision name="mori0_edge_1_collision">
        <pose>0.0 0.0 0.0 0.0 0.0 0.0</pose>
        <geometry>
          <mesh>
            <uri>/home/jonathan/Work/EPFL/PhD/Dev/FARMS/farms_amphibious/farms_amphibious/experiments/mori/meshes/mori_edge_1.stl</uri>
            <scale>0.001 0.001 0.001</scale>
          </mesh>
        </geometry>
      </collision>
      <visual name="mori0_edge_1_visual">
        <pose>0.0 0.0 0.0 0.0 0.0 0.0</pose>
        <geometry>
          <mesh>
            <uri>/home/jonathan/Work/EPFL/PhD/Dev/FARMS/farms_amphibious/farms_amphibious/experiments/mori/meshes/mori_edge_1.stl</uri>
            <scale>0.001 0.001 0.001</scale>
          </mesh>
        </geometry>
        <material/>
      </visual>
    </link>
    <link name="mori0_edge_2">
      <pose>0.18 0.0 0.0 0.0 0.0 2.0943951023931953</pose>
      <inertial>
        <pose>0.07156417686898321 0.0185706718415633 0.0004234654444363972 0.0 0.0 0.0</pose>
        <mass>0.01924244181778677</mass>
        <inertia>
          <ixx>2.202818616618582e-12</ixx>
          <ixy>-5.510346292622388e-14</ixy>
          <ixz>-2.4501383091352336e-13</ixz>
          <iyy>9.55478060604246e-12</iyy>
          <iyz>3.6269644572832477e-14</iyz>
          <izz>1.136128573230277e-11</izz>
        </inertia>
      </inertial>
      <collision name="mori0_edge_2_collision">
        <pose>0.0 0.0 0.0 0.0 0.0 0.0</pose>
        <geometry>
          <mesh>
            <uri>/home/jonathan/Work/EPFL/PhD/Dev/FARMS/farms_amphibious/farms_amphibious/experiments/mori/meshes/mori_edge_0.stl</uri>
            <scale>0.001 0.001 0.001</scale>
          </mesh>
        </geometry>
      </collision>
      <visual name="mori0_edge_2_visual">
        <pose>0.0 0.0 0.0 0.0 0.0 0.0</pose>
        <geometry>
          <mesh>
            <uri>/home/jonathan/Work/EPFL/PhD/Dev/FARMS/farms_amphibious/farms_amphibious/experiments/mori/meshes/mori_edge_0.stl</uri>
            <scale>0.001 0.001 0.001</scale>
          </mesh>
        </geometry>
        <material/>
      </visual>
    </link>
    <link name="mori0_edge_3">
      <pose>0.09 0.15588457268119893 0.0 0.0 0.0 2.0943951023931953</pose>
      <inertial>
        <pose>-0.05608217366573354 0.01813392473990149 -0.0006412053342845109 0.0 0.0 0.0</pose>
        <mass>0.012487966796885032</mass>
        <inertia>
          <ixx>1.8853112716181517e-12</ixx>
          <ixy>-6.858507706102207e-13</ixy>
          <ixz>-1.0983686520414591e-13</ixz>
          <iyy>3.513265983945765e-12</iyy>
          <iyz>-3.8764347262766245e-14</iyz>
          <izz>5.143951490951159e-12</izz>
        </inertia>
      </inertial>
      <collision name="mori0_edge_3_collision">
        <pose>0.0 0.0 0.0 0.0 0.0 0.0</pose>
        <geometry>
          <mesh>
            <uri>/home/jonathan/Work/EPFL/PhD/Dev/FARMS/farms_amphibious/farms_amphibious/experiments/mori/meshes/mori_edge_1.stl</uri>
            <scale>0.001 0.001 0.001</scale>
          </mesh>
        </geometry>
      </collision>
      <visual name="mori0_edge_3_visual">
        <pose>0.0 0.0 0.0 0.0 0.0 0.0</pose>
        <geometry>
          <mesh>
            <uri>/home/jonathan/Work/EPFL/PhD/Dev/FARMS/farms_amphibious/farms_amphibious/experiments/mori/meshes/mori_edge_1.stl</uri>
            <scale>0.001 0.001 0.001</scale>
          </mesh>
        </geometry>
        <material/>
      </visual>
    </link>
    <link name="mori0_edge_4">
      <pose>0.09 0.15588457268119893 0.0 0.0 0.0 4.188790204786391</pose>
      <inertial>
        <pose>0.07156417686898321 0.0185706718415633 0.0004234654444363972 0.0 0.0 0.0</pose>
        <mass>0.01924244181778677</mass>
        <inertia>
          <ixx>2.202818616618582e-12</ixx>
          <ixy>-5.510346292622388e-14</ixy>
          <ixz>-2.4501383091352336e-13</ixz>
          <iyy>9.55478060604246e-12</iyy>
          <iyz>3.6269644572832477e-14</iyz>
          <izz>1.136128573230277e-11</izz>
        </inertia>
      </inertial>
      <collision name="mori0_edge_4_collision">
        <pose>0.0 0.0 0.0 0.0 0.0 0.0</pose>
        <geometry>
          <mesh>
            <uri>/home/jonathan/Work/EPFL/PhD/Dev/FARMS/farms_amphibious/farms_amphibious/experiments/mori/meshes/mori_edge_0.stl</uri>
            <scale>0.001 0.001 0.001</scale>
          </mesh>
        </geometry>
      </collision>
      <visual name="mori0_edge_4_visual">
        <pose>0.0 0.0 0.0 0.0 0.0 0.0</pose>
        <geometry>
          <mesh>
            <uri>/home/jonathan/Work/EPFL/PhD/Dev/FARMS/farms_amphibious/farms_amphibious/experiments/mori/meshes/mori_edge_0.stl</uri>
            <scale>0.001 0.001 0.001</scale>
          </mesh>
        </geometry>
        <material/>
      </visual>
    </link>
    <link name="mori0_edge_5">
      <pose>0.0 0.0 0.0 0.0 0.0 4.188790204786391</pose>
      <inertial>
        <pose>-0.05608217366573354 0.01813392473990149 -0.0006412053342845109 0.0 0.0 0.0</pose>
        <mass>0.012487966796885032</mass>
        <inertia>
          <ixx>1.8853112716181517e-12</ixx>
          <ixy>-6.858507706102207e-13</ixy>
          <ixz>-1.0983686520414591e-13</ixz>
          <iyy>3.513265983945765e-12</iyy>
          <iyz>-3.8764347262766245e-14</iyz>
          <izz>5.143951490951159e-12</izz>
        </inertia>
      </inertial>
      <collision name="mori0_edge_5_collision">
        <pose>0.0 0.0 0.0 0.0 0.0 0.0</pose>
        <geometry>
          <mesh>
            <uri>/home/jonathan/Work/EPFL/PhD/Dev/FARMS/farms_amphibious/farms_amphibious/experiments/mori/meshes/mori_edge_1.stl</uri>
            <scale>0.001 0.001 0.001</scale>
          </mesh>
        </geometry>
      </collision>
      <visual name="mori0_edge_5_visual">
        <pose>0.0 0.0 0.0 0.0 0.0 0.0</pose>
        <geometry>
          <mesh>
            <uri>/home/jonathan/Work/EPFL/PhD/Dev/FARMS/farms_amphibious/farms_amphibious/experiments/mori/meshes/mori_edge_1.stl</uri>
            <scale>0.001 0.001 0.001</scale>
          </mesh>
        </geometry>
        <material/>
      </visual>
    </link>
    <link name="mori1_edge_0">
      <pose>0.18 0.0 0.0 0.0 0.0 1.0471975511965976</pose>
      <inertial>
        <pose>0.07156417686898321 0.0185706718415633 0.0004234654444363972 0.0 0.0 0.0</pose>
        <mass>0.01924244181778677</mass>
        <inertia>
          <ixx>2.202818616618582e-12</ixx>
          <ixy>-5.510346292622388e-14</ixy>
          <ixz>-2.4501383091352336e-13</ixz>
          <iyy>9.55478060604246e-12</iyy>
          <iyz>3.6269644572832477e-14</iyz>
          <izz>1.136128573230277e-11</izz>
        </inertia>
      </inertial>
      <collision name="mori1_edge_0_collision">
        <pose>0.0 0.0 0.0 0.0 0.0 0.0</pose>
        <geometry>
          <mesh>
            <uri>/home/jonathan/Work/EPFL/PhD/Dev/FARMS/farms_amphibious/farms_amphibious/experiments/mori/meshes/mori_edge_0.stl</uri>
            <scale>0.001 0.001 0.001</scale>
          </mesh>
        </geometry>
      </collision>
      <visual name="mori1_edge_0_visual">
        <pose>0.0 0.0 0.0 0.0 0.0 0.0</pose>
        <geometry>
          <mesh>
            <uri>/home/jonathan/Work/EPFL/PhD/Dev/FARMS/farms_amphibious/farms_amphibious/experiments/mori/meshes/mori_edge_0.stl</uri>
            <scale>0.001 0.001 0.001</scale>
          </mesh>
        </geometry>
        <material/>
      </visual>
    </link>
    <link name="mori1_edge_1">
      <pose>0.27 0.15588457268119893 0.0 0.0 0.0 1.0471975511965976</pose>
      <inertial>
        <pose>-0.05608217366573354 0.01813392473990149 -0.0006412053342845109 0.0 0.0 0.0</pose>
        <mass>0.012487966796885032</mass>
        <inertia>
          <ixx>1.8853112716181517e-12</ixx>
          <ixy>-6.858507706102207e-13</ixy>
          <ixz>-1.0983686520414591e-13</ixz>
          <iyy>3.513265983945765e-12</iyy>
          <iyz>-3.8764347262766245e-14</iyz>
          <izz>5.143951490951159e-12</izz>
        </inertia>
      </inertial>
      <collision name="mori1_edge_1_collision">
        <pose>0.0 0.0 0.0 0.0 0.0 0.0</pose>
        <geometry>
          <mesh>
            <uri>/home/jonathan/Work/EPFL/PhD/Dev/FARMS/farms_amphibious/farms_amphibious/experiments/mori/meshes/mori_edge_1.stl</uri>
            <scale>0.001 0.001 0.001</scale>
          </mesh>
        </geometry>
      </collision>
      <visual name="mori1_edge_1_visual">
        <pose>0.0 0.0 0.0 0.0 0.0 0.0</pose>
        <geometry>
          <mesh>
            <uri>/home/jonathan/Work/EPFL/PhD/Dev/FARMS/farms_amphibious/farms_amphibious/experiments/mori/meshes/mori_edge_1.stl</uri>
            <scale>0.001 0.001 0.001</scale>
          </mesh>
        </geometry>
        <material/>
      </visual>
    </link>
    <link name="mori1_edge_2">
      <pose>0.27 0.15588457268119893 0.0 0.0 0.0 3.141592653589793</pose>
      <inertial>
        <pose>0.07156417686898321 0.0185706718415633 0.0004234654444363972 0.0 0.0 0.0</pose>
        <mass>0.01924244181778677</mass>
        <inertia>
          <ixx>2.202818616618582e-12</ixx>
          <ixy>-5.510346292622388e-14</ixy>
          <ixz>-2.4501383091352336e-13</ixz>
          <iyy>9.55478060604246e-12</iyy>
          <iyz>3.6269644572832477e-14</iyz>
          <izz>1.136128573230277e-11</izz>
        </inertia>
      </inertial>
      <collision name="mori1_edge_2_collision">
        <pose>0.0 0.0 0.0 0.0 0.0 0.0</pose>
        <geometry>
          <mesh>
            <uri>/home/jonathan/Work/EPFL/PhD/Dev/FARMS/farms_amphibious/farms_amphibious/experiments/mori/meshes/mori_edge_0.stl</uri>
            <scale>0.001 0.001 0.001</scale>
          </mesh>
        </geometry>
      </collision>
      <visual name="mori1_edge_2_visual">
        <pose>0.0 0.0 0.0 0.0 0.0 0.0</pose>
        <geometry>
          <mesh>
            <uri>/home/jonathan/Work/EPFL/PhD/Dev/FARMS/farms_amphibious/farms_amphibious/experiments/mori/meshes/mori_edge_0.stl</uri>
            <scale>0.001 0.001 0.001</scale>
          </mesh>
        </geometry>
        <material/>
      </visual>
    </link>
    <link name="mori1_edge_3">
      <pose>0.09 0.15588457268119893 0.0 0.0 0.0 3.141592653589793</pose>
      <inertial>
        <pose>-0.05608217366573354 0.01813392473990149 -0.0006412053342845109 0.0 0.0 0.0</pose>
        <mass>0.012487966796885032</mass>
        <inertia>
          <ixx>1.8853112716181517e-12</ixx>
          <ixy>-6.858507706102207e-13</ixy>
          <ixz>-1.0983686520414591e-13</ixz>
          <iyy>3.513265983945765e-12</iyy>
          <iyz>-3.8764347262766245e-14</iyz>
          <izz>5.143951490951159e-12</izz>
        </inertia>
      </inertial>
      <collision name="mori1_edge_3_collision">
        <pose>0.0 0.0 0.0 0.0 0.0 0.0</pose>
        <geometry>
          <mesh>
            <uri>/home/jonathan/Work/EPFL/PhD/Dev/FARMS/farms_amphibious/farms_amphibious/experiments/mori/meshes/mori_edge_1.stl</uri>
            <scale>0.001 0.001 0.001</scale>
          </mesh>
        </geometry>
      </collision>
      <visual name="mori1_edge_3_visual">
        <pose>0.0 0.0 0.0 0.0 0.0 0.0</pose>
        <geometry>
          <mesh>
            <uri>/home/jonathan/Work/EPFL/PhD/Dev/FARMS/farms_amphibious/farms_amphibious/experiments/mori/meshes/mori_edge_1.stl</uri>
            <scale>0.001 0.001 0.001</scale>
          </mesh>
        </geometry>
        <material/>
      </visual>
    </link>
    <link name="mori1_edge_4">
      <pose>0.09 0.15588457268119893 0.0 0.0 0.0 5.235987755982989</pose>
      <inertial>
        <pose>0.07156417686898321 0.0185706718415633 0.0004234654444363972 0.0 0.0 0.0</pose>
        <mass>0.01924244181778677</mass>
        <inertia>
          <ixx>2.202818616618582e-12</ixx>
          <ixy>-5.510346292622388e-14</ixy>
          <ixz>-2.4501383091352336e-13</ixz>
          <iyy>9.55478060604246e-12</iyy>
          <iyz>3.6269644572832477e-14</iyz>
          <izz>1.136128573230277e-11</izz>
        </inertia>
      </inertial>
      <collision name="mori1_edge_4_collision">
        <pose>0.0 0.0 0.0 0.0 0.0 0.0</pose>
        <geometry>
          <mesh>
            <uri>/home/jonathan/Work/EPFL/PhD/Dev/FARMS/farms_amphibious/farms_amphibious/experiments/mori/meshes/mori_edge_0.stl</uri>
            <scale>0.001 0.001 0.001</scale>
          </mesh>
        </geometry>
      </collision>
      <visual name="mori1_edge_4_visual">
        <pose>0.0 0.0 0.0 0.0 0.0 0.0</pose>
        <geometry>
          <mesh>
            <uri>/home/jonathan/Work/EPFL/PhD/Dev/FARMS/farms_amphibious/farms_amphibious/experiments/mori/meshes/mori_edge_0.stl</uri>
            <scale>0.001 0.001 0.001</scale>
          </mesh>
        </geometry>
        <material/>
      </visual>
    </link>
    <link name="mori1_edge_5">
      <pose>0.18 0.0 0.0 0.0 0.0 5.235987755982989</pose>
      <inertial>
        <pose>-0.05608217366573354 0.01813392473990149 -0.0006412053342845109 0.0 0.0 0.0</pose>
        <mass>0.012487966796885032</mass>
        <inertia>
          <ixx>1.8853112716181517e-12</ixx>
          <ixy>-6.858507706102207e-13</ixy>
          <ixz>-1.0983686520414591e-13</ixz>
          <iyy>3.513265983945765e-12</iyy>
          <iyz>-3.8764347262766245e-14</iyz>
          <izz>5.143951490951159e-12</izz>
        </inertia>
      </inertial>
      <collision name="mori1_edge_5_collision">
        <pose>0.0 0.0 0.0 0.0 0.0 0.0</pose>
        <geometry>
          <mesh>
            <uri>/home/jonathan/Work/EPFL/PhD/Dev/FARMS/farms_amphibious/farms_amphibious/experiments/mori/meshes/mori_edge_1.stl</uri>
            <scale>0.001 0.001 0.001</scale>
          </mesh>
        </geometry>
      </collision>
      <visual name="mori1_edge_5_visual">
        <pose>0.0 0.0 0.0 0.0 0.0 0.0</pose>
        <geometry>
          <mesh>
            <uri>/home/jonathan/Work/EPFL/PhD/Dev/FARMS/farms_amphibious/farms_amphibious/experiments/mori/meshes/mori_edge_1.stl</uri>
            <scale>0.001 0.001 0.001</scale>
          </mesh>
        </geometry>
        <material/>
      </visual>
    </link>
    <joint name="mori0_joint_0" type="prismatic">
      <parent>mori0_edge_0</parent>
      <child>mori0_edge_1</child>
      <pose>0.0 0.0 0.0 0.0 0.0 0.0</pose>
      <axis>
        <xyz>1 0 0</xyz>
        <limit>
          <lower>0.0</lower>
          <upper>0.012</upper>
          <effort>0.0</effort>
          <velocity>10000000000.0</velocity>
        </limit>
      </axis>
    </joint>
    <joint name="mori0_joint_1" type="revolute">
      <parent>mori0_edge_1</parent>
      <child>mori0_edge_2</child>
      <pose>0.0 0.0 0.0 0.0 0.0 0.0</pose>
      <axis>
        <xyz>0 0 1</xyz>
        <limit>
          <lower>-31.41592653589793</lower>
          <upper>31.41592653589793</upper>
          <effort>0</effort>
          <velocity>10000000000.0</velocity>
        </limit>
      </axis>
    </joint>
    <joint name="mori0_joint_2" type="prismatic">
      <parent>mori0_edge_2</parent>
      <child>mori0_edge_3</child>
      <pose>0.0 0.0 0.0 0.0 0.0 0.0</pose>
      <axis>
        <xyz>1 0 0</xyz>
        <limit>
          <lower>0.0</lower>
          <upper>0.012</upper>
          <effort>0.0</effort>
          <velocity>10000000000.0</velocity>
        </limit>
      </axis>
    </joint>
    <joint name="mori0_joint_3" type="revolute">
      <parent>mori0_edge_3</parent>
      <child>mori0_edge_4</child>
      <pose>0.0 0.0 0.0 0.0 0.0 0.0</pose>
      <axis>
        <xyz>0 0 1</xyz>
        <limit>
          <lower>-31.41592653589793</lower>
          <upper>31.41592653589793</upper>
          <effort>0</effort>
          <velocity>10000000000.0</velocity>
        </limit>
      </axis>
    </joint>
    <joint name="mori0_joint_4" type="prismatic">
      <parent>mori0_edge_4</parent>
      <child>mori0_edge_5</child>
      <pose>0.0 0.0 0.0 0.0 0.0 0.0</pose>
      <axis>
        <xyz>1 0 0</xyz>
        <limit>
          <lower>0.0</lower>
          <upper>0.012</upper>
          <effort>0.0</effort>
          <velocity>10000000000.0</velocity>
        </limit>
      </axis>
    </joint>
    <joint name="mori1_joint_0" type="prismatic">
      <parent>mori1_edge_0</parent>
      <child>mori1_edge_1</child>
      <pose>0.0 0.0 0.0 0.0 0.0 0.0</pose>
      <axis>
        <xyz>1 0 0</xyz>
        <limit>
          <lower>0.0</lower>
          <upper>0.012</upper>
          <effort>0.0</effort>
          <velocity>10000000000.0</velocity>
        </limit>
      </axis>
    </joint>
    <joint name="mori1_joint_1" type="revolute">
      <parent>mori1_edge_1</parent>
      <child>mori1_edge_2</child>
      <pose>0.0 0.0 0.0 0.0 0.0 0.0</pose>
      <axis>
        <xyz>0 0 1</xyz>
        <limit>
          <lower>-31.41592653589793</lower>
          <upper>31.41592653589793</upper>
          <effort>0</effort>
          <velocity>10000000000.0</velocity>
        </limit>
      </axis>
    </joint>
    <joint name="mori1_joint_2" type="prismatic">
      <parent>mori1_edge_2</parent>
      <child>mori1_edge_3</child>
      <pose>0.0 0.0 0.0 0.0 0.0 0.0</pose>
      <axis>
        <xyz>1 0 0</xyz>
        <limit>
          <lower>0.0</lower>
          <upper>0.012</upper>
          <effort>0.0</effort>
          <velocity>10000000000.0</velocity>
        </limit>
      </axis>
    </joint>
    <joint name="mori1_joint_3" type="revolute">
      <parent>mori1_edge_3</parent>
      <child>mori1_edge_4</child>
      <pose>0.0 0.0 0.0 0.0 0.0 0.0</pose>
      <axis>
        <xyz>0 0 1</xyz>
        <limit>
          <lower>-31.41592653589793</lower>
          <upper>31.41592653589793</upper>
          <effort>0</effort>
          <velocity>10000000000.0</velocity>
        </limit>
      </axis>
    </joint>
    <joint name="mori1_joint_4" type="prismatic">
      <parent>mori1_edge_4</parent>
      <child>mori1_edge_5</child>
      <pose>0.0 0.0 0.0 0.0 0.0 0.0</pose>
      <axis>
        <xyz>1 0 0</xyz>
        <limit>
          <lower>0.0</lower>
          <upper>0.012</upper>
          <effort>0.0</effort>
          <velocity>10000000000.0</velocity>
        </limit>
      </axis>
    </joint>
    <joint name="connection0_1" type="revolute">
      <parent>mori0_edge_2</parent>
      <child>mori1_edge_0</child>
      <pose>0.0 0.0 0.0 0.0 0.0 0.0</pose>
      <axis>
        <xyz>1 0 0</xyz>
        <limit>
          <lower>-31.41592653589793</lower>
          <upper>31.41592653589793</upper>
          <effort>0</effort>
          <velocity>10000000000.0</velocity>
        </limit>
      </axis>
    </joint>
  </model>
</sdf>
